Workbook

Sheet INDUK1
I4: KEMENTRIAN KEUANGAN | Y4: SPT TAHUNAN | AP4: INDUK
I5: REPUBLIK INDONESIA | Y5: PAJAK PENGHASILAN (PPh) | AP5: HALAMAN 1
I6: DIREKTORAT JENDERAL PAJAK | Y6: WAJIB PAJAK BADAN
Y7: DALAM MATA UANG RUPIAH
BA8: UMUM
E9: TAHUN PAJAK/BAGIAN TAHUN PAJAK | Q9: PERIODE PEMBUKUAN | AC9: STATUS | AK9: METODE PEMBUKUAN | BA9: DAGANG
G10: TAHUN PAJAK | Q10: BULAN MULAI | V10: BULAN AKHIR | BA10: JASA
G12: BAGIAN TAHUN PAJAK | AE12: NORMAL | AM12: PEMBUKUAN STELSEL AKRUAL
E14: 2 | G14: 0 | I14: 2 | K14: 5 | Q14: 0 | R14: 1 | S14: S . D | V14: 1 | W14: 2 | AE14: PEMBETULAN | AM14: PEMBUKUAN STELSEL KAS
D18: A. | E18: IDENTITAS WAJIB PAJAK
E21: 1. | F21: NPWP
E23: 2. | F23: NAMA
E25: 3. | F25: ALAMAT EMAIL
E27: 4. | F27: NOMOR TELEPON
D31: B. | E31: INFORMASI LAPORANKEUANGAN
E33: 1 | F33: Sektor Usaha Laporan Keuangan pada Lampiran 1
E35: 2 | F35: Apakah Laporan Keuangan diaudit oleh Akuntan Publik ? | AG35: TIDAK | AK35: YA | AM35: Opini Auditor
F36: Jika "Ya", isilah informasi mengenai Kantor akuntan Publik di bawah ini:
F37: a. | G37: NPWP Kantor Akuntan Publik
F39: b. | G39: Nama Kantor akuntan Publik
D42: C. | E42: PENGHASILAN YANG DIKENAKAN PPh YANG BERSIFAT FINAL DANPENGHASILAN YANG TIDAK TERMASUK OBJEK PAJAK
E44: 1 | G44: a | H44: Apakah Wajib Pajak menerima atau memperoleh penghasilan dari usaha dengan peredaran bruto tertentu yang dikenakan PPh yang bersifat final ? | AJ44: TIDAK | AN44: YA
H46: Jika "Ya", isilah Lampiran 5
G47: b | H47: Apakah penghasilan Wajib Pajak semata-mata hanya penghasilan dari usaha dengan peredaran bruto tertentu yang dikenakan PPh yang bersifat final ?
AJ48: TIDAK | AN48: YA
E50: 2 | F50: Apakah wajib Pajak menerima atau memperoleh penghasilan yang dikenakan PPh yang bersifat final ? | AJ50: TIDAK | AN50: YA
F51: Jika "Ya", Isilah Lampiran 4 bagian A.
E53: 3 | F53: Apakah Wajib Pajak menerima atau memperoleh penghasilan yang tidak termasuk objek pajak ? | AJ53: TIDAK | AN53: YA
F54: Jika "Ya", Isilah Lampiran 4 bagian B.
D57: D. | E57: PENGHITUNGAN PPh
E59: 4 | F59: Penghasilan Neto Fiskal sebelum Fasilitas Pajak
F60: Diisi dari Lampiran 1 (sesuai sektor usaha) Bagian A Kolom (10)
E62: 5 | F62: Apakah Wajib Pajak memperoleh Fasilitas Perpajakan dalam rangka Penanaman Modal berupa pengurangan penghasilan neto ? | AJ62: TIDAK | AN62: YA
F64: Jika "Ya", isilah Lampiran 13A
E66: 6 | F66: Apakah Wajib Pajak memperoleh Fasilitas Pengurangan Penghasilan Bruto atas Kegiatan Praktik Kerja, Pemagangan, dan/atau Pembelajaran dalam rangka Pembinaan dan Pengembangan Sumber Daya Manusia Berbasis Kompetensi Tertentu ? | AJ66: TIDAK | AN66: YA
F69: Jika "Ya", isilah Lampiran 13B
E71: 7 | F71: Penghasilan Neto Fiskal Setelah Fasilitas Pajak | AF71: ( | AG71: 4 | AH71: - | AI71: 5 | AJ71: - | AK71: 6 | AL71: ) | AP71: =AP59-AP62-AP66 -> 0
E73: 8 | F73: Apakah terdapat kerugian fiskal yang dapat dikompensasikan ? | AJ73: TIDAK | AN73: YA
F74: Jika "Ya", isilah Lampiran 7
E76: 9 | F76: Penghasilan Kena Pajak | AF76: ( | AG76: 7 | AH76: - | AI76: 8 | AJ76: ) | AP76: =AP71-AP73 -> 0
...

Sheet INDUK2
I4: KEMENTRIAN KEUANGAN | Y4: SPT TAHUNAN | AP4: INDUK
I5: REPUBLIK INDONESIA | Y5: PAJAK PENGHASILAN (PPh) | AP5: HALAMAN 2
I6: DIREKTORAT JENDERAL PAJAK | Y6: WAJIB PAJAK BADAN
Y7: DALAM MATA UANG RUPIAH
E9: TAHUN PAJAK/BAGIAN TAHUN PAJAK | Q9: PERIODE PEMBUKUAN | AC9: STATUS | AK9: METODE PEMBUKUAN
G10: TAHUN PAJAK | Q10: BULAN MULAI | V10: BULAN AKHIR
G12: BAGIAN TAHUN PAJAK | AE12: NORMAL | AM12: PEMBUKUAN STELSEL AKRUAL
E14: =INDUK1!E14 -> 2 | G14: =INDUK1!G14 -> 0 | I14: =INDUK1!I14 -> 2 | K14: =INDUK1!K14 -> 5 | Q14: 0 | R14: 1 | S14: S . D | V14: 1 | W14: 2 | AE14: PEMBETULAN | AM14: PEMBUKUAN STELSEL KAS
E19: 19 | G19: a | H19: Lebih Bayar pada Angka 17 atau 18b mohon untuk: (pilih salah satu)
I21: dikembalikan melalui pemeriksaan
I23: dikembalikan melalui pengembalian pendahuluan
G25: b | H25: Infromasi Rekening
H26: Nomor Rekening | AA26: Nama Bank
H28: Nama Pemilik Rekening
H29: Jika Informasi rekening salah, silahkan melakukan perubahan data pada menu Registrasi
D32: G. | E32: PENGHITUNGAN ANGSURAN PPh PASAL 25 TAHUN BERJALAN
E34: 20 | F34: Apakah Wajib Pajak merupakan Wajib Pajak tertentu yang harus menyampaikan Laporan Penghitungan Angsuran PPh Pasal 25 ? | AJ34: TIDAK | AN34: YA
F36: Jika "Tidak", isilah Lampiran 6
F37: Jika "Ya", pastikan Anda menyampaikan Laporan Penghitungan PPh Pasal 25 sesuai ketentuan perundang-undangan yang berlaku.
D40: H. | E40: PERNYATAAN TRANSAKSI
E42: 21 | G42: a | H42: Apakah terdapat transaksi yang dipengaruhi hubungan istimewa atau transaksi dengan pihak yang merupakan penduduk tax haven country ? | AQ42: TIDAK | AU42: YA
H44: Jika "Ya", isilah Lampiran 10A, 10B, dan 10C
G46: b | H46: Apakah Wajib Pajak berkewajiban menyampaikan Dokumen Penentuan Harga Transfer? | AQ46: TIDAK | AU46: YA
H47: Jika "Ya", isilah Lampiran 10D
G49: c | H49: Apakah terdapat penanaman modal pada perusahaan afiliasi? | AQ49: TIDAK | AU49: YA
H50: Jika "Ya", isilah Lampiran 2 Bagian B
G52: d | H52: Apakah Wajib Pajak memiliki utang dari pemilik modal atau perusahaan afiliasi, dan/atau piutang ke pemilik modal atau perusahaan afiliasi? | AQ52: TIDAK | AU52: YA
H54: Jika "Ya", isilah Lampiran 2 Bagian B
G56: e | H56: Apakah Wajib Pajak membebankan biaya penyusutan dan/atau amortisasi fiskal? | AQ56: TIDAK | AU56: YA
H57: Jika "Ya", isilah Lampiran 9
G59: f | H59: Apakah Wajib Pajak membebankan biaya promosi dan penjualan, penggantian atau imbalan dalam bentuk natura dan/atau kenikmatan, biaya entertainment, dan/atau piutang yang nyata-nyata tidak dapat ditagih? | AQ59: TIDAK | AU59: YA
H61: Jika "Ya", isilah Lampiran 11A
G63: g | H63: Apakah Wajib Pajak memperoleh fasilitas perpajakan dalam rangka penanaman modal di bidang-bidang usaha tertentu dan/atau daerah-daerah tertentu selain pengurangan penghasilan neto? | AQ63: TIDAK | AU63: YA
H65: Jika "Ya", isilah Lampiran 13A
G67: h | H67: Apakah Wajib Pajak memiliki sisa lebih yang digunakan untuk pembangunan dan pengadaan saran dan prasarana ? | AQ67: TIDAK | AU67: YA
H68: Jika "Ya", isilah Lampiran 14
G70: i | H70: apakah Wajib Pajak menerima atau memperoleh [enghasilan dividen dari luar negeri dan melaporkannya sebagai penghasilan yang tidak termasuk objek pajak ? | AQ70: TIDAK | AU70: YA
H72: Jika "Ya", sampaikan Laporan Realisasi Investasi secara terpisah sesuai dengan ketentuan perundang-undangan yang berlaku
G74: j | H74: Kelebihan PPh yang bersifat final atas penghasilan dari usaha dengan peredaran bruto tertentu yang dapat diajukan pengembalian pajak
H76: Diisi dari Lampiran 5 (jika terdapat kelebihan PPh, silahkan mengajukan permohonan pengembalian pajak secara terpisah)
...

Sheet LKUMUM
E3: UMUM | AN3: LAMPIRAN 1A
N4: SPT TAHUNAN
D5: PERHATIAN | N5: PAJAK PENGHASILAN (PPh) WAJIB PAJAK BADAN
D6: Formulir ini wajib diisi oleh Wajib Pajak badan dengan sektor usaha SELAIN dari sektor usaha yang telah ditentukan pada Lampiran 1B s.d. Lampiran 1L
N7: (DALAM MATA UANG RUPIAH) | AN7: TAHUN PAJAK/BAGIAN PAJAK
O8: REKONSILIASI LAPORAN KEUANGAN | AP8: =INDUK1!E14 -> 2 | AQ8: =INDUK1!G14 -> 0 | AR8: =INDUK1!I14 -> 2 | AS8: =INDUK1!K14 -> 5
O10: NPWP | R10: =INDUK1!AF21 -> 0 | S10: =INDUK1!AG21 -> 0 | T10: =INDUK1!AH21 -> 0 | U10: =INDUK1!AI21 -> 0 | V10: =INDUK1!AJ21 -> 0 | W10: =INDUK1!AK21 -> 0 | X10: =INDUK1!AL21 -> 0 | Y10: =INDUK1!AM21 -> 0 | ... AG10: =INDUK1!AU21 -> 0
D13: A. | E13: LAPORAN LABA RUGI
D15: KODE AKUN | F15: NAMA AKUN | P15: NILAI (KOMERSIAL) | T15: TIDAK TERMASUK OBJEK PAJAK | X15: DIKENAKAN PPh BERSIFAT FINAL | AB15: OBJEK PAJAK TIDAK FINAL | AF15: PENYESUAIAN FISKAL POSITF | AJ15: PENYESUAIAN FISKAL NEGATIF | AN15: KODE PENYUSUNAN FISKAL | AR15: NILAI FISKAL (Sebelum Fasilitas Perpajakan)
D18: (1) | F18: (2) | P18: (3) | T18: (4) | X18: (5) | AB18: (6) = (3) - (4) - (5) | AF18: (7) | AJ18: (8) | AN18: (9) | AR18: (10)
F19: Penjualan
D20: 4002 | F20: Penjualan Domestik
D21: 4003 | F21: Penjualan Ekspor
D22: 4004 | F22: Penjualan Bruto
F23: Dikurangi
D24: 4011 | G24: Retur
D25: 4012 | G25: Potongan Penjualan
D26: 4013 | G26: Penyesuaian Penjualan
D27: 4020 | F27: Penjualan Bersih
F28: Harga Pokok Penjualan (HPP)
D29: 5001 | G29: Pembelian
D30: 5003 | G30: Beban Pengangkutan
D31: 5007 | G31: Beban Lainnya
D32: 5008 | G32: Persediaan - Awal
D33: 5009 | H33: Dikurangi Persediaan - Akhir
D34: 5020 | G34: Jumlah HPP
D35: 4300 | F35: Laba Kotor
D36: 4199 | F36: Pendapatan Usaha Lainnya
F37: Beban Usaha
D38: 5311 | G38: Gaji, Tunjangan, Bonus, Honorarium, THR, dsb
D39: 5312 | G39: Beban Imbalan Kerja Lainnya
D40: 5313 | G40: Beban Transportasi
D41: 5314 | G41: Beban Sewa
D42: 4315 | G42: Beban Penyusutan dan Amortisasi
D43: 4316 | G43: Beban Bunga
D44: 4317 | G44: Beban sehubungan dengan Jasa
D45: 5318 | G45: Beban Penurunan Nilai
D46: 5319 | G46: Beban Royalti
D47: 5320 | G47: Beban Pemasaran atau Promosi
D48: 5321 | G48: Beban Entertainment
...

Sheet LKDAGANG
E3: UMUM | AN3: LAMPIRAN 1C
N4: SPT TAHUNAN
D5: PERHATIAN | N5: PAJAK PENGHASILAN (PPh) WAJIB PAJAK BADAN
D6: Formulir ini wajib diisi oleh Wajib Pajak badan sektor PERDAGANGAN
N7: (DALAM MATA UANG RUPIAH) | AN7: TAHUN PAJAK/BAGIAN PAJAK
O8: REKONSILIASI LAPORAN KEUANGAN | AP8: =INDUK1!E14 -> 2 | AQ8: =INDUK1!G14 -> 0 | AR8: =INDUK1!I14 -> 2 | AS8: =INDUK1!K14 -> 5
O10: NPWP | R10: =INDUK1!AF21 -> 0 | S10: =INDUK1!AG21 -> 0 | T10: =INDUK1!AH21 -> 0 | U10: =INDUK1!AI21 -> 0 | V10: =INDUK1!AJ21 -> 0 | W10: =INDUK1!AK21 -> 0 | X10: =INDUK1!AL21 -> 0 | Y10: =INDUK1!AM21 -> 0 | ... AG10: =INDUK1!AU21 -> 0
D13: A. | E13: LAPORAN LABA RUGI
D15: KODE AKUN | F15: NAMA AKUN | P15: NILAI (KOMERSIAL) | T15: TIDAK TERMASUK OBJEK PAJAK | X15: DIKENAKAN PPh BERSIFAT FINAL | AB15: OBJEK PAJAK TIDAK FINAL | AF15: PENYESUAIAN FISKAL POSITF | AJ15: PENYESUAIAN FISKAL NEGATIF | AN15: KODE PENYUSUNAN FISKAL | AR15: NILAI FISKAL (Sebelum Fasilitas Perpajakan)
D18: (1) | F18: (2) | P18: (3) | T18: (4) | X18: (5) | AB18: (6) = (3) - (4) - (5) | AF18: (7) | AJ18: (8) | AN18: (9) | AR18: (10)
F19: Penjualan
D20: 4002 | F20: Penjualan Domestik
D21: 4003 | F21: Penjualan Ekspor
D22: 4004 | F22: Penjualan Bruto
F23: Dikurangi
D24: 4011 | G24: Retur
D25: 4012 | G25: Potongan Penjualan
D26: 4013 | G26: Penyesuaian Penjualan
D27: 4020 | F27: Penjualan Bersih
F28: Harga Pokok Penjualan (HPP)
D29: 5001 | G29: Pembelian
D30: 5003 | G30: Beban Pengangkutan
D31: 5007 | G31: Beban Lainnya
D32: 5008 | G32: Persediaan - Awal
D33: 5009 | H33: Dikurangi Persediaan - Akhir
D34: 5020 | G34: Jumlah HPP
D35: 4300 | F35: Laba Kotor
D36: 4199 | F36: Pendapatan Usaha Lainnya
F37: Beban Usaha
D38: 5311 | G38: Gaji, Tunjangan, Bonus, Honorarium, THR, dsb
D39: 5312 | G39: Beban Imbalan Kerja Lainnya
D40: 5313 | G40: Beban Transportasi
D41: 5314 | G41: Beban Sewa
D42: 4315 | G42: Beban Penyusutan dan Amortisasi
D43: 4316 | G43: Beban Bunga
D44: 4317 | G44: Beban sehubungan dengan Jasa
D45: 5318 | G45: Beban Penurunan Nilai
D46: 5319 | G46: Beban Royalti
D47: 5320 | G47: Beban Pemasaran atau Promosi
D48: 5321 | G48: Beban Entertainment
...

Sheet LKJASA
E3: UMUM | AN3: LAMPIRAN 1D
N4: SPT TAHUNAN
D5: PERHATIAN | N5: PAJAK PENGHASILAN (PPh) WAJIB PAJAK BADAN
D6: Formulir ini wajib diisi oleh Wajib Pajak badan sektor JASA
N7: (DALAM MATA UANG RUPIAH) | AN7: TAHUN PAJAK/BAGIAN PAJAK
O8: REKONSILIASI LAPORAN KEUANGAN | AP8: =INDUK1!E14 -> 2 | AQ8: =INDUK1!G14 -> 0 | AR8: =INDUK1!I14 -> 2 | AS8: =INDUK1!K14 -> 5
O10: NPWP | R10: =INDUK1!AF21 -> 0 | S10: =INDUK1!AG21 -> 0 | T10: =INDUK1!AH21 -> 0 | U10: =INDUK1!AI21 -> 0 | V10: =INDUK1!AJ21 -> 0 | W10: =INDUK1!AK21 -> 0 | X10: =INDUK1!AL21 -> 0 | Y10: =INDUK1!AM21 -> 0 | ... AG10: =INDUK1!AU21 -> 0
D13: A. | E13: LAPORAN LABA RUGI
D15: KODE AKUN | F15: NAMA AKUN | P15: NILAI (KOMERSIAL) | T15: TIDAK TERMASUK OBJEK PAJAK | X15: DIKENAKAN PPh BERSIFAT FINAL | AB15: OBJEK PAJAK TIDAK FINAL | AF15: PENYESUAIAN FISKAL POSITF | AJ15: PENYESUAIAN FISKAL NEGATIF | AN15: KODE PENYUSUNAN FISKAL | AR15: NILAI FISKAL (Sebelum Fasilitas Perpajakan)
D18: (1) | F18: (2) | P18: (3) | T18: (4) | X18: (5) | AB18: (6) = (3) - (4) - (5) | AF18: (7) | AJ18: (8) | AN18: (9) | AR18: (10)
F19: Pendapatan
D20: 4021 | F20: Pendapatan Jasa
D21: 4013 | F21: Penyesuaian Penjualan
D22: 5020 | F22: Biaya Pokok Jasa
D23: 4300 | F23: Laba Kotor
D24: 4199 | F24: Pendapatan Usaha Lainnya
F25: Beban Usaha
D26: 5311 | G26: Gaji, Tunjangan, Bonus, Honorarium, THR, dsb
D27: 5312 | G27: Beban Imbalan Kerja Lainnya
D28: 5313 | G28: Beban Transportasi
D29: 5314 | G29: Beban Sewa
D30: 4315 | G30: Beban Penyusutan dan Amortisasi
D31: 4316 | G31: Beban Bunga
D32: 4317 | G32: Beban sehubungan dengan Jasa
D33: 5318 | G33: Beban Penurunan Nilai
D34: 5319 | G34: Beban Royalti
D35: 5320 | G35: Beban Pemasaran atau Promosi
D36: 5321 | G36: Beban Entertainment
D37: 5322 | G37: Beban Umum dan Administrasi
... D39: 5400 | G39: Jumlah Beban Usaha
D40: 4500 | F40: Laba (Rugi) Usaha
F41: Pendapatan Non Usaha
D42: 4501 | F42: Keuntungan Selisih Kurs
D43: 4503 | F43: Keuntungan Penjualan Aset selain Persediaan
D44: 4511 | F44: Pendapatan Bunga
D45: 4599 | F45: Pendapatan Non Usaha Lainnya
D46: 4600 | F46: Jumlah Pendapatan Non Usaha
F47: Beban Non Usaha
D48: 5405 | G48: Kerugian Penjualan Aset selain Persediaan
D49: 5409 | G49: Sumbangan
...

Sheet L2
E3: UMUM | AQ3: LAMPIRAN 2
N4: SPT TAHUNAN
D5: PERHATIAN | N5: PAJAK PENGHASILAN (PPh) WAJIB PAJAK BADAN
D6: Formulir ini wajib diisi oleh seluruh Wajib Pajak Badan
N7: (DALAM MATA UANG RUPIAH) | AQ7: TAHUN PAJAK/BAGIAN PAJAK
O8: DAFTAR KEPEMILIKAN | AS8: =INDUK1!E14 -> 2 | AT8: =INDUK1!G14 -> 0 | AU8: =INDUK1!I14 -> 2 | AV8: =INDUK1!K14 -> 5
O10: NPWP | R10: =INDUK1!AF21 -> 0 | S10: =INDUK1!AG21 -> 0 | T10: =INDUK1!AH21 -> 0 | U10: =INDUK1!AI21 -> 0 | V10: =INDUK1!AJ21 -> 0 | W10: =INDUK1!AK21 -> 0 | X10: =INDUK1!AL21 -> 0 | Y10: =INDUK1!AM21 -> 0 | ... AG10: =INDUK1!AU21 -> 0
D13: A. | E13: DAFTAR PEMEGANG SAHAM/PEMILIK MODAL DAN JUMLAH DIVIDEN/PEMBAGIAN LABA YANG DIBAGIKAN SERTA DAFTAR SUSUNAN PENGURUS DAN KOMISARIS
D15: NO. | E15: NAMA | M15: ALAMAT | U15: NEGARA | Y15: NPWP/NIK | AE15: JABATAN | AK15: MODAL DISETOR | AQ15: % | AS15: DIVIDEN/PEMBAGIAN LABA
AK16: NILAI (Rp) | AS16: (Rp)
D17: (1) | E17: (2) | M17: (3) | U17: (4) | Y17: (5) | AE17: (6) | AK17: (7) | AQ17: (8) | AS17: (9)
D23: JUMLAH | AK23: =SUM(AK18:AK22) -> 0 | AQ23: =SUM(AQ18:AQ22) -> 0 | AS23: =SUM(AS18:AS22) -> 0
D25: B. | E25: DAFTAR PENYERTAAN MODAL, UTANG, DAN/ATAU PIUTANG PADA PERUSAHAAN AFILIASI
D27: NO. | E27: NAMA | M27: NEGARA | Q27: NPWP/NIK | W27: PENYERTAAN MODAL | AC27: UTANG | AN27: PIUTANG
W28: NILAI (Rp) | AA28: % | AC28: NILAI (Rp) | AH28: TAHUN | AJ28: BUNGA/TAHUN | AN28: NILAI (Rp) | AT28: TAHUN | AV28: BUNGA/TAHUN
D29: (1) | E29: (2) | M29: (3) | Q29: (4) | W29: (5) | AA29: (6) | AC29: (7) | AH29: (8) | AJ29: (9) | AN29: (10) | AT29: (11) | AV29: (12)
D35: TOTAL | AC35: =SUM(AC30:AC34) -> 0 | AN35: =SUM(AN30:AN34) -> 0
AU37: HOME

Sheet L3
AN3: LAMPIRAN 3
D4: PERHATIAN | N4: SPT TAHUNAN
D5: Formulir ini digunakan untuk Wajib Pajak yang memperoleh/menerima penghasilan yang dipotong/dipungut PPh oleh pihak lain | N5: PAJAK PENGHASILAN (PPh) WAJIB PAJAK BADAN
N7: DALAM MATA UANG RUPIAH | AN7: TAHUN PAJAK/BAGIAN PAJAK
N8: DAFTAR PPh YANG DIPOTONG/DIPUNGUT OLEH PIHAK LAIN | AP8: =INDUK1!E14 -> 2 | AQ8: =INDUK1!G14 -> 0 | AR8: =INDUK1!I14 -> 2 | AS8: =INDUK1!K14 -> 5
O10: NPWP | R10: =INDUK1!AF21 -> 0 | S10: =INDUK1!AG21 -> 0 | T10: =INDUK1!AH21 -> 0 | U10: =INDUK1!AI21 -> 0 | V10: =INDUK1!AJ21 -> 0 | W10: =INDUK1!AK21 -> 0 | X10: =INDUK1!AL21 -> 0 | Y10: =INDUK1!AM21 -> 0 | ... AG10: =INDUK1!AU21 -> 0
D13: A. | E13: PENGHASILAN DARI LUAR NEGERI
D15: NO. | E15: PEMOTONG PAJAK | N15: TANGGAL PAJAK PENGHASILAN TERUTANG/DIBAYAR/DIPOTONG | S15: JENIS PENGHASILAN | W15: PENGHASILAN NETO (Rp) | AB15: PAJAK PENGHASILAN TERUTANG/DIBAYAR/DIPOTONG DI LUAR NEGERI | AP15: KREDIT PAJAK YANG DAPAT DIPERHITUNGKAN (Rp)
E17: NAMA | J17: NEGARA | AB17: NILAI (Rp) | AG17: MATA UANG | AK17: NILAI (DALAM MATA UANG ASING)
D19: (1) | E19: (2) | J19: (3) | N19: (4) | S19: (5) | W19: (6) | AB19: (7) | AG19: (8) | AK19: (9) | AP19: (10)
D20: 1
D21: 2
D22: 3
D23: 4
D24: 5
D25: 6
D26: 7
D27: 8
D28: JUMLAH | W28: =SUM(W20:W27) -> 0 | AB28: =SUM(AB20:AB27) -> 0 | AN28: a | AP28: =SUM(AP20:AP27) -> 0
D29: PENGEMBALIAN PERNGURANGAN KREDIT PAJAK LUAR NEGERI (PPh PASAL 24) YANG TELAH DIPERHITUNGKAN TAHUN LALU | AN29: b | AP29: 0
D30: JUMLAH KREDIT PAJAK LUAR NGERI YANG DAPAT DIPERHITUNGKAN TAHUN BERJALAN | AH30: ( | AI30: a | AJ30: - | AK30: b | AL30: ) | AN30: c | AP30: =AP28-AP29 -> 0
D33: B. | E33: PPh YANG DIPOTONG/DIPUNGUT PIHAK LAIN
D35: NO. | E35: PEMOTONG/PEMUNGUT PAJAK | S35: JENIS PAJAK | W35: DASAR PENGENAAN PAJAK | AE35: PPh YANG DIPOTONG/DIPUNGUT | AM35: BUKTI PEMOTONGAN/SSP/SSPCP
E37: NAMA | L37: NPWP | W37: (Rp) | AE37: (Rp) | AM37: NOMOR | AR37: TANGGAL
D38: (1) | E38: (2) | L38: (3) | S38: (4) | W38: (5) | AE38: (6) | AM38: (7) | AR38: (8)
D39: 1
D40: 2
D41: 3
D42: 4
D43: 5
D44: 6
D45: 7
D46: 8
D47: 9
D48: JUMLAH | U48: b | W48: =SUM(W39:W47) -> 0 | AE48: =SUM(AE39:AE47) -> 0
D49: KREDIT PAJAK LUAR NEGERI (Diisi dari Bagian A.c. Kolom (10)) | AC49: b | AE49: =AP30 -> 0
D50: JUMLAH KREDIT PAJAK | W50: ( | X50: a | Y50: - | Z50: b | AA50: ) | AC50: b | AE50: =AE48-AE49 -> 0
D51: Pindahkan JUMLAH KREDIT PAJAK kolom 6 field C ke Formulir Induk Bagian E.13
AS52: HOME

Sheet L4
AK3: LAMPIRAN 4
D4: PERHATIAN | N4: SPT TAHUNAN
D5: Formulir ini digunakan untuk Wajib Pajak yang menerima penghasilan yang dikenakan PPh yang bersifat Final dan penghasilan yang tidak termasuk objek pajak | N5: PAJAK PENGHASILAN (PPh) WAJIB PAJAK BADAN
N7: DALAM MATA UANG RUPIAH | AK7: TAHUN PAJAK/BAGIAN PAJAK
N8: PENGHASILAN YANG DIKENAKAN PPh YANG BERSIFAT FINAL DAN PENGHASILAN YANG TIDAK TERMASUK OBJEK PAJAK | AM8: =INDUK1!E14 -> 2 | AN8: =INDUK1!G14 -> 0 | AO8: =INDUK1!I14 -> 2 | AP8: =INDUK1!K14 -> 5
O11: NPWP | R11: =INDUK1!AF21 -> 0 | S11: =INDUK1!AG21 -> 0 | T11: =INDUK1!AH21 -> 0 | U11: =INDUK1!AI21 -> 0 | V11: =INDUK1!AJ21 -> 0 | W11: =INDUK1!AK21 -> 0 | X11: =INDUK1!AL21 -> 0 | Y11: =INDUK1!AM21 -> 0 | ... AG11: =INDUK1!AU21 -> 0
D14: A. | E14: PENGHASILAN YANG DIKENAKAN PPh YANG BERSIFAT FINAL
D16: NO. | E16: PEMOTONG/PEMUNGUT PAJAK | U16: KODE OBJEK PAJAK | Y16: OBJEK PAJAK | AC16: DASAR PENGENAAN PAJAK | AJ16: TARIF | AL16: PPh TERUTANG
E17: NPWP | L17: NAMA | AC17: (Rp) | AJ17: (%) | AL17: (Rp)
D18: (1) | E18: (2) | L18: (3) | U18: (4) | Y18: (5) | AC18: (6) | AJ18: (7) | AL18: (8)
D27: JUMLAH | AA27: A.6 | AC27: =SUM(AC19:AC26) -> 0 | AL27: =SUM(AL19:AL26) -> 0
D28: Pindahkan hasil penjumlahan Bagian A kolom 4 (A.6) ke Formulir Induk Bagian C.2
D30: B. | E30: PENGHASILAN YANG TIDAK TERMASUK OBJEK PAJAK
D32: NO. | E32: KODE JENIS PENGHASILAN | N32: JENIS PENGHASILAN | X32: SUMBER PENGHASILAN | AJ32: PENGHASILAN BRUTO
D34: (1) | E34: (2) | N34: (3) | X34: (4) | AJ34: (5)
D43: JUMLAH | AH43: B.5 | AJ43: =SUM(AJ35:AJ42) -> 0
D44: Pindahkan hasil penjumlahan Bagian B kolom 5 (B.5) ke Formulir Induk bagian C.3
AP45: HOME

Sheet L5
AP3: LAMPIRAN 5
D4: PERHATIAN | O4: SPT TAHUNAN
D5: Formulir ini digunakan untuk Wajib Pajak yang menerima atau memperoleh penghasilan dari usaha dengan peredaran bruto tertentu yang dikenakan PPh yang bersifat final | O5: PAJAK PENGHASILAN (PPh) WAJIB PAJAK BADAN
O7: DALAM MATA UANG RUPIAH | AP7: TAHUN PAJAK/BAGIAN PAJAK
O8: REKAPITULASI PEREDARAN BRUTO | AR8: =INDUK1!E14 -> 2 | AS8: =INDUK1!G14 -> 0 | AT8: =INDUK1!I14 -> 2 | AU8: =INDUK1!K14 -> 5
P10: NPWP | S10: =INDUK1!AF21 -> 0 | T10: =INDUK1!AG21 -> 0 | U10: =INDUK1!AH21 -> 0 | V10: =INDUK1!AI21 -> 0 | W10: =INDUK1!AJ21 -> 0 | X10: =INDUK1!AK21 -> 0 | Y10: =INDUK1!AL21 -> 0 | Z10: =INDUK1!AM21 -> 0 | ... AH10: =INDUK1!AU21 -> 0
D13: A. | E13: ALAMAT TEMPAT KEGIATAN USAHA
D15: NOMOR IDENTITAS TEMPAT KEGIATAN USAHA | M15: NAMA TKU | S15: ALAMAT | Z15: KELURAHAN/DESA | AG15: KECAMATAN | AM15: KOTA/KABUPATEN | AS15: PROVINSI
D17: (1) | M17: (2) | S17: (3) | Z17: (4) | AG17: (5) | AM17: (6) | AS17: (7)
D22: B. | E22: REKAPITULASI PEREDARAN BRUTO DAN PPh YANG TELAH DIBAYAR
D24: NAMA TKU | J24: JANUARI | M24: FEBRUARI | P24: MARET | S24: APRIL | V24: MEI | Y24: JUNI | AB24: JULI | AE24: AGUSTUS | AH24: SEPTEMBER | AK24: OKTOBER | AN24: NOVEMBER | AQ24: DESEMBER | AT24: JUMLAH
D26: (1) | J26: (2) | M26: (3) | P26: (4) | S26: (5) | V26: (6) | Y26: (7) | AB26: (8) | AE26: (9) | AH26: (10) | AK26: (11) | AN26: (12) | AQ26: (13) | AT26: (14)
J27: 1000000 | M27: 1000000 | P27: 1000000 | S27: 1000000 | V27: 1000000 | Y27: 1000000 | AB27: 1000000 | AE27: 1000000 | AH27: 1000000 | AK27: 1000000 | AN27: 1000000 | AQ27: 1000000 | AT27: =SUM(J27:AQ27) -> 12000000
AT28: =SUM(J28:AQ28) -> 0
AT29: =SUM(J29:AQ29) -> 0
AT30: =SUM(J30:AQ30) -> 0
AT31: =SUM(J31:AQ31) -> 0
AT32: =SUM(J32:AQ32) -> 0
AT33: =SUM(J33:AQ33) -> 0
D34: JUMLAH PEREDARAN BRUTO | J34: =SUM(J27:J33) -> 1000000 | M34: =SUM(M27:M33) -> 1000000 | P34: =SUM(P27:P33) -> 1000000 | S34: =SUM(S27:S33) -> 1000000 | V34: =SUM(V27:V33) -> 1000000 | Y34: =SUM(Y27:Y33) -> 1000000 | AB34: =SUM(AB27:AB33) -> 1000000 | AE34: =SUM(AE27:AE33) -> 1000000 | AH34: =SUM(AH27:AH33) -> 1000000 | AK34: =SUM(AK27:AK33) -> 1000000 | AN34: =SUM(AN27:AN33) -> 1000000 | AQ34: =SUM(AQ27:AQ33) -> 1000000 | AT34: a.15 | AU34: =SUM(AT27:AT33) -> 12000000
D36: JUMLAH PPh BERSIFAT FINAL TERUTANG | J36: =J34 -> 1000000 | M36: =M34 -> 1000000 | P36: =P34 -> 1000000 | S36: =S34 -> 1000000 | V36: =V34 -> 1000000 | Y36: =Y34 -> 1000000 | AB36: =AB34 -> 1000000 | AE36: =AE34 -> 1000000 | AH36: =AH34 -> 1000000 | AK36: =AK34 -> 1000000 | AN36: =AN34 -> 1000000 | AQ36: =AQ34 -> 1000000 | AT36: =SUM(J36:AQ36) -> 12000000
D38: JUMLAH PPh BERSIFAT FINAL YANG DISETOR SENDIRI | J38: =J36*0.5/100 -> 5000 | M38: =M36*0.5/100 -> 5000 | P38: =P36*0.5/100 -> 5000 | S38: =S36*0.5/100 -> 5000 | V38: =V36*0.5/100 -> 5000 | Y38: =Y36*0.5/100 -> 5000 | AB38: =AB36*0.5/100 -> 5000 | AE38: =AE36*0.5/100 -> 5000 | AH38: =AH36*0.5/100 -> 5000 | AK38: =AK36*0.5/100 -> 5000 | AN38: =AN36*0.5/100 -> 5000 | AQ38: =AQ36*0.5/100 -> 5000 | AT38: =SUM(J38:AQ38) -> 60000
D41: JUMLAH PPh BERSIFAT FINAL YANG DIPOTONG/DIPUNGUT PIHAK LAIN | J41: 0 | M41: 0 | P41: 0 | S41: 0 | V41: 0 | Y41: 0 | AB41: 0 | AE41: 0 | AH41: 0 | AK41: 0 | AN41: 0 | AQ41: 0 | AT41: =SUM(J41:AQ41) -> 0
D45: SELISIH | J45: =J38-J41 -> 5000 | M45: =M38-M41 -> 5000 | P45: =P38-P41 -> 5000 | S45: =S38-S41 -> 5000 | V45: =V38-V41 -> 5000 | Y45: =Y38-Y41 -> 5000 | AB45: =AB38-AB41 -> 5000 | AE45: =AE38-AE41 -> 5000 | AH45: =AH38-AH41 -> 5000 | AK45: =AK38-AK41 -> 5000 | AN45: =AN38-AN41 -> 5000 | AQ45: =AQ38-AQ41 -> 5000 | AT45: e.15 | AU45: =SUM(J45:AQ45) -> 60000
D46: SELISIH PADA SPT YANG DIBETULKAN
D47: SELISIH KARENA PEMBETULAN | AT47: g.15
AV49: HOME

Sheet L6
AN3: LAMPIRAN 6
D4: PERHATIAN | N4: SPT TAHUNAN
D5: Formulir ini digunakan untuk Wajib Pajak yang diwajibkan melakukan penyetoran PPh Pasal 25 | N5: PAJAK PENGHASILAN (PPh) WAJIB PAJAK BADAN
N7: DALAM MATA UANG RUPIAH | AN7: TAHUN PAJAK/BAGIAN PAJAK
O8: ANGSURAN PPh TAHUN PAJAK BERJALAN | AP8: =INDUK1!E14 -> 2 | AQ8: =INDUK1!G14 -> 0 | AR8: =INDUK1!I14 -> 2 | AS8: =INDUK1!K14 -> 5
O10: NPWP | R10: =INDUK1!AF21 -> 0 | S10: =INDUK1!AG21 -> 0 | T10: =INDUK1!AH21 -> 0 | U10: =INDUK1!AI21 -> 0 | V10: =INDUK1!AJ21 -> 0 | W10: =INDUK1!AK21 -> 0 | X10: =INDUK1!AL21 -> 0 | Y10: =INDUK1!AM21 -> 0 | ... AG10: =INDUK1!AU21 -> 0
AM14: NILAI (Rp)
E16: 1 | G16: PENGHASILAN YANG MENJADI DASAR PENGHITUNGAN ANGSURAN
E19: 2 | G19: KOMPENSASI KERUGIAN Diisi dari Formulir Lampiran 7 Jumlah Kompensasi Kerugian Fiskal Tahun Pajak Berjalan)
E22: 3 | G22: PENGHASILAN KENA PAJAK | AM22: =AM16-AM19 -> 0
AA23: ( | AB23: 1 | AC23: - | AD23: 2 | AE23: )
E25: 4 | G25: PPh YANG TERUTANG
AA26: ( | AB26: Tarif | AD26: X | AE26: 3 | AF26: )
E28: 5 | G28: KREDIT PAJAK TAHUN PAJAK YANG LALU ATAS PENGHASILAN YANG TERMASUK DALAM ANGKA 1 YANG DIPOTONG/DIPUNGUT PIHAK LAIN
E31: 6 | G31: PPh YANG HARUS DI BAYAR SENDIRI | AM31: =AM25-AM28 -> 0
AA32: ( | AB32: 4 | AC32: - | AD32: 5 | AE32: )
E34: 7 | G34: ANGSURAN PPh PASAL 25 | AM34: =(1/AC35*AM31) -> 0
AA35: ( | AB35: 1/ | AC35: 12 | AD35: * | AE35: X | AF35: 6 | AG35: ) | AK35: 7
AI36: Pindahkan nilai pada angka 7 ke Formulir Induk bagian G
D38: *) | E38: Diisi dengan jumlah Masa Pajak dalam Tahun Pajak/Bagian Tahun Pajak SPT yang Dilaporkan
AO39: HOME

Sheet L7
AY3: LAMPIRAN 7
D4: PERHATIAN | V4: SPT TAHUNAN
D5: Formulir ini digunakan untuk Wajib Pajak yang memiliki Kerugian Fiskal yang dapat dikompensasikan | V5: PAJAK PENGHASILAN (PPh) WAJIB PAJAK BADAN
V7: DALAM MATA UANG RUPIAH | AY7: TAHUN PAJAK/BAGIAN PAJAK
V8: PENGHITUNGAN KOMPENSASI KERUGIAN FISKAL | BB8: =INDUK1!E14 -> 2 | BC8: =INDUK1!G14 -> 0 | BD8: =INDUK1!I14 -> 2 | BE8: =INDUK1!K14 -> 5
W10: NPWP | Z10: =INDUK1!AF21 -> 0 | AA10: =INDUK1!AG21 -> 0 | AB10: =INDUK1!AH21 -> 0 | AC10: =INDUK1!AI21 -> 0 | AD10: =INDUK1!AJ21 -> 0 | AE10: =INDUK1!AK21 -> 0 | AF10: =INDUK1!AL21 -> 0 | AG10: =INDUK1!AM21 -> 0 | ... AO10: =INDUK1!AU21 -> 0
D13: NO. | E13: LABA (RUGI) NETO FISKAL | M13: KOMPENSASI KERUGIAN FISKAL
N15: TAHUN | V15: TAHUN | AD15: TAHUN | AL15: TAHUN | AT15: TAHUN | BB15: TAHUN
E17: TAHUN/BAGIAN TAHUN PAJAK | I17: NILAI (Rp) | M17: NILAI (Rp) | U17: NILAI (Rp) | AC17: NILAI (Rp) | AK17: NILAI (Rp) | AS17: TAHUN PAJAK INI | BA17: TAHUN PAJAK BERJALAN
M18: (Y-4) | U18: (Y-3) | AC18: (Y-2) | AK18: (Y-1) | AS18: NILAI (Rp)* | BA18: NILAI (Rp)**
D19: (1) | E19: (2) | I19: (3) | M19: (4) | U19: (5) | AC19: (6) | AK19: (7) | AS19: (8) | BA19: (9)
D27: JUMLAH | AS27: 8 | AT27: =SUM(AS20:AS26) -> 0 | BA27: 9 | BB27: =SUM(BA20:BA26) -> 0
D28: * | E28: Jumlah Kolom (8) digunakan sebagai pengurang penghasilan neto pada Formulir Induk bagian D.8
D29: ** | E29: Jumlah Kolom (9) digunakan sebagai pengurang penghasilan neto pada Formulir Lampiran 6 Angka 2 | BC29: HOME

Sheet L8
AM3: LAMPIRAN 8
D4: PERHATIAN | N4: SPT TAHUNAN
D5: Formulir ini digunakan untuk Wajib Pajak yang berhak menggunakan tarif sebagaimana Pasal 31E ayat (1) UU PPh | N5: PAJAK PENGHASILAN (PPh) WAJIB PAJAK BADAN
N7: DALAM MATA UANG RUPIAH | AM7: TAHUN PAJAK/BAGIAN PAJAK
O8: PENGHITUNGAN FASILITAS PENGURANGAN TARIF PPh BAGI WAJIB PAJAKJ BADAN DALAM NEGERI BERDASARKAN PASAL 31 E AYAT (1) UNDANG-UNDANG PPh*) | AO8: =INDUK1!E14 -> 2 | AP8: =INDUK1!G14 -> 0 | AQ8: =INDUK1!I14 -> 2 | AR8: =INDUK1!K14 -> 5
O11: NPWP | R11: =INDUK1!AF21 -> 0 | S11: =INDUK1!AG21 -> 0 | T11: =INDUK1!AH21 -> 0 | U11: =INDUK1!AI21 -> 0 | V11: =INDUK1!AJ21 -> 0 | W11: =INDUK1!AK21 -> 0 | X11: =INDUK1!AL21 -> 0 | Y11: =INDUK1!AM21 -> 0 | ... AG11: =INDUK1!AU21 -> 0
AL15: NILAI (Rupiah)
E17: 1 | G17: PEREDARAN BRUTO
G18: Jumlah Peredaran Bruto
E20: 2 | G20: PENGHASILAN KENA PAJAK
G21: a | H21: Penghasilan kena Pajak dari Bagian Peredaran Bruto yang memperoleh Fasilitas **)
H22: ((Rp 4.800.000.000 / Jumlah Peredaran Bruto) X Penghasilan Kena Pajak)
G24: b | H24: Penghasilan Kena Pajak dari Bagian Peredaran Bruto yang Tidak memperoleh Fasilitas
H25: (Penghasilan Kena Pajak - Penghasilan Kena Pajak dari Bagian Peredaran Bruto yang memperoleh Fasilitas)
E27: 3 | G27: PPh TERUTANG
G28: a | H28: PPh Terutang atas Penghasilan Kena Pajak dari Bagian Peredaran Bruto yang memperoleh Fasilitas
H29: ( 50 % X Tarif Pasal 17 ayat (1) X Penghasilan Kena Pajak dari bagian peredaran bruto yang memperoleh fasilitas)
G31: b | H31: PPh Terutang atas Penghasilan Kena Pajak dari Bagian Peredaran Bruto yang tidak memperoleh Fasilitas
H32: (Tarif Pasal 17 ayat (1) huruf b UU PPh X Penghasilan Kena Pajak dari Bagian Peredaran bruto yang memperoleh fasilitas)
E34: 4 | G34: JUMLAH PPh TERUTANG
AE35: ( | AF35: 3a | AG35: + | AH35: 3b | AI35: )
AG37: Pindahkan Jumlah PPh Terutang ke Formulir Induk bagian D.12
D40: Keterangan :
D41: *) | E41: Penghitungan ini hanya di buat oleh Wajib Pajak Badan Dalam Negeri dengan peredaran bruto sampai dengan Rp 50.000.000.000,00 (Lima Puluh miliar Rupiah)
D42: **) | E42: Dalam hal peredaran bruto sampai dengan Rp 4.800.000.000,00 (Empat Miliar Delapan Ratus Juta Rupiah), seluruh Penghasilan Kena Pajak merupakan Penghasilan Kena Pajak dari bagian peredaran bruto yang memperoleh fasilitas
AP45: HOME

Sheet L9
AU3: LAMPIRAN 9
D4: PERHATIAN | T4: SPT TAHUNAN
D5: Formulir ini wajib diisi oleh Wajib Pajak yang membebankan biaya penyusutan dan/atau amortisasi | T5: PAJAK PENGHASILAN (PPh) WAJIB PAJAK BADAN
T7: DALAM MATA UANG RUPIAH | AU7: TAHUN PAJAK/BAGIAN PAJAK
T8: DAFTAR PENYUSUTAN DAN AMORTISASI FISKAL | AX8: =INDUK1!E14 -> 2 | AY8: =INDUK1!G14 -> 0 | AZ8: =INDUK1!I14 -> 2 | BA8: =INDUK1!K14 -> 5
U10: NPWP | X10: =INDUK1!AF21 -> 0 | Y10: =INDUK1!AG21 -> 0 | Z10: =INDUK1!AH21 -> 0 | AA10: =INDUK1!AI21 -> 0 | AB10: =INDUK1!AJ21 -> 0 | AC10: =INDUK1!AK21 -> 0 | AD10: =INDUK1!AL21 -> 0 | AE10: =INDUK1!AM21 -> 0 | ... AM10: =INDUK1!AU21 -> 0
D13: KODE HARTA | G13: KELOMPOK/JENIS HARTA | S13: BULAN/TAHUN PEROLEHAN | W13: BIAYA PEROLEHAN | AB13: NISALI SISA BUKU FISKAL PADA AWAL TAHUN | AG13: METODE PENYUSUTAN/AMORTISASI | AM13: PENYUSUTAN/AMORTISASI FISKAL TAHUN INI | AS13: KETERANGAN
AG15: KOMERSIAL | AJ15: FISKAL | AM15: (Rp)
D16: (1) | G16: (2) | S16: (3) | W16: (4) | AB16: (5) | AG16: (6) | AJ16: (7) | AM16: (8) | AS16: (9)
G17: I. | H17: HARTA BERWUJUD
H18: A. | I18: Kelompok 1
I19: 1.
I20: 2.
I21: 3.
H22: B. | I22: Kelompok 2
I23: 1.
I24: 2.
I25: 3.
H26: C. | I26: Kelompok 3
I27: 1.
I28: 2.
I29: 3.
H30: D. | I30: Kelompok 4
I31: 1.
I32: 2.
I33: 3.
G34: II. | H34: KELOMPOK BANGUNAN
H35: A. | I35: Permanen
I36: 1.
I37: 2.
H38: B. | I38: Tidak Permanen
I39: 1.
I40: 2.
D41: a. | E41: JUMLAH PENYUSUTAN FISKAL
D42: b. | E42: JUMLAH PENYUSUTAN KOMERSIAL
D43: c. | E43: SELISIH PENYUSUTAN (a - b)
G44: III. | H44: HARTA TAK BERWUJUD
H45: A. | I45: Kelompok 1
I46: 1.
I47: 2.
...

Sheet L11A
AO3: LAMPIRAN 11A
D4: PERHATIAN | O4: SPT TAHUNAN
D5: Formulir ini diisi oleh Wajib Pajak yang wajib menyampaikan rincian atas biaya-biaya tertentu | O5: PAJAK PENGHASILAN (PPh) WAJIB PAJAK BADAN
O7: DALAM MATA UANG RUPIAH | AO7: TAHUN PAJAK/BAGIAN PAJAK
P8: RINCIAN BIAYA TERTENTU | AR8: =INDUK1!E14 -> 2 | AS8: =INDUK1!G14 -> 0 | AT8: =INDUK1!I14 -> 2 | AU8: =INDUK1!K14 -> 5
P11: NPWP | S11: =INDUK1!AF21 -> 0 | T11: =INDUK1!AG21 -> 0 | U11: =INDUK1!AH21 -> 0 | V11: =INDUK1!AI21 -> 0 | W11: =INDUK1!AJ21 -> 0 | X11: =INDUK1!AK21 -> 0 | Y11: =INDUK1!AL21 -> 0 | Z11: =INDUK1!AM21 -> 0 | ... AH11: =INDUK1!AU21 -> 0
D14: I. | E14: DAFTAR NOMINATIF/BIAYA PROMOSI DAN PENJUALAN SERTA PENGGANTIAN ATAU IMBALAN DALAM BENTUK NATURA DAN/ATAU KENIKMATAN
D16: NO. | E16: DATA PENERIMA | AP16: PEMOTONGAN/PEMUNGUTAN PPh
E17: NOMOR IDENTITAS | K17: NAMA | R17: ALAMAT | X17: TANGGAL | AB17: JENIS BIAYA | AF17: NILAI | AJ17: KETERANGAN | AP17: JUMLAH PPh | AT17: NOMOR BUKTI PEMOTONGAN/PEMUNGUTAN
E18: (NPWP/NIK/Lain-lain) | AF18: (Rp) | AP18: (Rp)
D20: (1) | E20: (2) | K20: (3) | R20: (4) | X20: (5) | AB20: (6) | AF20: (7) | AJ20: (8) | AP20: (9) | AT20: (10)
D26: II. | E26: DAFTAR NOMINATIF BIAYA ENTERTAINMEN
D28: NO. | E28: PEMBERIAN ENTERTAINMENT | AA28: RELASI USAHA YANG DIBERIKAN ENTERTAINMENT | AU28: KETERANGAN
E29: TANGGAL | I29: TEMPAT | M29: ALAMAT | S29: JENIS | W29: NILAI | AA29: NAMA | AF29: JABATAN | AK29: NAMA PERUSAHAAN | AQ29: JENIS USAHA
W30: (Rp)
D32: (1) | E32: (2) | I32: (3) | M32: (4) | S32: (5) | W32: (6) | AA32: (7) | AF32: (8) | AK32: (9) | AQ32: (10) | AU32: (11)
D38: III. | E38: DAFTAR PIUTANG YANG NYATA-NYATA TIDAK DAPAT DITAGIH
D40: NO. | E40: NOMOR IDENTITAS | K40: NAMA | Q40: ALAMAT | X40: PLAFON PIUTANG | AD40: PIUTANG YANG NYATA-NYATA TIDAK DAPAT DITAGIH | AK40: METODE PEMBEBANAN | AR40: JENIS DIKUMEN PEMBUKTIAN YANG DIISYARATKAN
E42: (NPWP/NIK/Lain-lain) | X42: (Rp)
AD43: (Rp)
D44: (1) | E44: (2) | K44: (3) | Q44: (4) | X44: (5) | AD44: (6) | AK44: (7) | AR44: (8)
D50: IV. | E50: RINCIAN BAGI WAJIB PAJAK PEMBERI NATURA DAN/ATAU KENIKMATAN
D52: IV.A | E52: DAFTAR SARANA DAN FASILITAS SERTA PENYUSUTANNYA
E53: NO. | F53: JENIS HARTA BERWUJUD | Q53: TAHUN PEROLEHAN | U53: NILAI PEROLEHAN | AC53: PENYUSUTAN
U54: (Rp) | AC54: S.D. TAHUN LALU | AJ54: TAHUN INI | AR54: S.D. TAHUN INI
E55: (1) | F55: (2) | Q55: (3) | U55: (4) | AC55: (5) | AJ55: (6) | AR55: (7)
D60: IV.B | E60: RINCIAN PENGGANTIAN ATAU IMBALAN DALAM BENTUK NATURA DAN/ATAU KENIKMATAN YANG DIBERIKAN BERKENAAN DENGAN PELAKSANAAN PEKERJAAN DI DAERAH TERTENTU
AO62: NILAI (Rupiah)
E64: 1 | F64: Alamat Lokasi | T64: :
E66: 2 | F66: Keputusan Penetapan Daerah Tertentu | T66: : | U66: Nomor | AE66: Tanggal
E68: 3 | F68: Keputusan Perpanjangan Penetapan Daerah Tertentu | T68: : | U68: Nomor | AE68: Tanggal
E70: 4 | F70: Biaya yang Dikeluarkan untuk:
F72: a | G72: tempat tinggal, termasuk perumahan untuk pegawai dan keluarganya
F74: b | G74: pelayanan kesehatan
F76: c | G76: pendidikan bagi pegawai dan keluarganya
F78: d | G78: peribadatan
F80: e | G80: pengangkutan bagi pegawai dan keluarganya
F82: f | G82: olahraga bagi pegawai dan keluarganya, tidak termasuk golf, power boating, pacuan kuda, dan terbang layang
F84: Jumlah Biaya yang di keluarkan | Z84: ( | AA84: 4a | AB84: + | AC84: 4b | AD84: + | AE84: 4c | AF84: + | AG84: 4d | AH84: + | AI84: 4e | AJ84: + | AK84: 4f | AL84: ) | AO84: =SUM(AO72:AW82) -> 0
D86: V. | E86: DAFTAR DEBITUR NON-PERFORMING LOAN
...

Sheet L11B
AZ3: LAMPIRAN 11B
D4: PERHATIAN | P4: SPT TAHUNAN
D5: Formulir ini diisi oleh semua Wajib Pajak Badan | P5: PAJAK PENGHASILAN (PPh) WAJIB PAJAK BADAN
P7: DALAM MATA UANG RUPIAH | AZ7: TAHUN PAJAK/BAGIAN PAJAK
Q8: PENGHITUNGAN BIAYA PINJAMAN YANG DAPAT DIBEBANKAN UNTUK KEPERLUAN PENGHITUNGAN PAJAK PENGHASILAN | BB8: =INDUK1!E14 -> 2 | BC8: =INDUK1!G14 -> 0 | BD8: =INDUK1!I14 -> 2 | BE8: =INDUK1!K14 -> 5
Q11: NPWP | T11: =INDUK1!AF21 -> 0 | U11: =INDUK1!AG21 -> 0 | V11: =INDUK1!AH21 -> 0 | W11: =INDUK1!AI21 -> 0 | X11: =INDUK1!AJ21 -> 0 | Y11: =INDUK1!AK21 -> 0 | Z11: =INDUK1!AL21 -> 0 | AA11: =INDUK1!AM21 -> 0 | ... AI11: =INDUK1!AU21 -> 0
D15: I. | E15: PENGHITUNGAN EBITDA
AY18: JUMLAH (Rp)
E20: 1 | F20: PENGHASILAN NETO KOMERSIAL
E22: 2 | F22: BEBAN PENYUSUTAN DAN AMORTISASI
E24: 3 | F24: BEBAN PAJAK PENGHASILAN
E26: 4 | F26: BEBAN BIAYA PINJAMAN
E28: 5 | F28: EBITDA
E30: 6 | F30: EBITDA (25%)
D33: II. | E33: PERBANDINGAN ANTARA UTANG DAN MODAL (DEBT TO EQUITY RATIO)
E35: A. | F35: PENGHITUNGAN SALDO RATA-RATA UTANG
E37: PEMBERI PINJAMAN | U37: SALDO UTANG TIAP AKHIR BULAN (Rp)
E39: NOMOR IDENTITAS | K39: NAMA | Q39: JENIS | U39: BULAN | X39: BULAN | AA39: BULAN | AD39: BULAN | AG39: BULAN | AJ39: BULAN | AM39: BULAN | AP39: BULAN | AS39: BULAN | AV39: BULAN | AY39: BULAN | BB39: BULAN | BE39: RATA-RATA
E40: (NPWP/NIK/Lain-lain) | U40: KE-1 | X40: KE-2 | AA40: KE-3 | AD40: KE-4 | AG40: KE-5 | AJ40: KE-6 | AM40: KE-7 | AP40: KE-8 | AS40: KE-9 | AV40: KE-10 | AY40: KE-11 | BB40: KE-12
E41: (1) | K41: (2) | Q41: (3) | U41: (4) | X41: (5) | AA41: (6) | AD41: (7) | AG41: (8) | AJ41: (9) | AM41: (10) | AP41: (11) | AS41: (12) | AV41: (13) | AY41: (14) | BB41: (15) | BE41: (16)
E47: JUMLAH | U47: =SUM(U42:U46) -> 0 | X47: =SUM(X42:X46) -> 0 | AA47: =SUM(AA42:AA46) -> 0 | AD47: =SUM(AD42:AD46) -> 0 | AG47: =SUM(AG42:AG46) -> 0 | AJ47: =SUM(AJ42:AJ46) -> 0 | AM47: =SUM(AM42:AM46) -> 0 | AP47: =SUM(AP42:AP46) -> 0 | AS47: =SUM(AS42:AS46) -> 0 | AV47: =SUM(AV42:AV46) -> 0 | AY47: =SUM(AY42:AY46) -> 0 | BB47: =SUM(BB42:BB46) -> 0 | BE47: =SUM(BE42:BE46) -> 0
E49: B. | F49: PENGHITUNGAN SALDO RATA-RATA MODAL
E51: RINCIAN MODAL | U51: SALDO MODAL TIAP AKHIR BULAN (Rp)
U53: BULAN | X53: BULAN | AA53: BULAN | AD53: BULAN | AG53: BULAN | AJ53: BULAN | AM53: BULAN | AP53: BULAN | AS53: BULAN | AV53: BULAN | AY53: BULAN | BB53: BULAN | BE53: RATA-RATA
U54: KE-1 | X54: KE-2 | AA54: KE-3 | AD54: KE-4 | AG54: KE-5 | AJ54: KE-6 | AM54: KE-7 | AP54: KE-8 | AS54: KE-9 | AV54: KE-10 | AY54: KE-11 | BB54: KE-12
E55: (1) | U55: (2) | X55: (3) | AA55: (4) | AD55: (5) | AG55: (6) | AJ55: (7) | AM55: (8) | AP55: (9) | AS55: (10) | AV55: (11) | AY55: (12) | BB55: (13) | BE55: (14)
E56: Modal Saham
E57: ..................
E58: ..................
E59: ..................
E60: Pinjaman Tanpa Bunga dari ................ | U60: 0
E61: JUMLAH | U61: =SUM(U56:U60) -> 0 | X61: =SUM(X56:X60) -> 0 | AA61: =SUM(AA56:AA60) -> 0 | AD61: =SUM(AD56:AD60) -> 0 | AG61: =SUM(AG56:AG60) -> 0 | AJ61: =SUM(AJ56:AJ60) -> 0 | AM61: =SUM(AM56:AM60) -> 0 | AP61: =SUM(AP56:AP60) -> 0 | AS61: =SUM(AS56:AS60) -> 0 | AV61: =SUM(AV56:AV60) -> 0 | AY61: =SUM(AY56:AY60) -> 0 | BB61: =SUM(BB56:BB60) -> 0 | BE61: =SUM(BE56:BE60) -> 0
E63: C. | F63: PENGHITUNGAN BESARNYA PERBANDINGAN ANTARA UTANG DANMODAL (DEBT TO EQUITY RATIO)
E66: DEBT TO EQUITY RATIO (DER) | N66: = | O66: Jumlah saldo Rata-rata Utang | Y66: = | AH66: = | AP66: :
O67: Jumlah saldo Rata-rata Modal
D69: III. | E69: PENGHITUNGAN BIAYA PINJAMAN
D71: PEMBERI PINJAMAN | O71: SALDO RATA-RATA UTANG | Z71: BIAYA PINJAMAN BUNGA | AH71: BIAYA PINJAMAN YANG DAPAT DIPERHITUNGKAN | AT71: BIAYA PINJAMAN YANG TIDAK DAPAT DIPERHITUNGKAN
D73: (1) | O73: (2) | Z73: (3) | AH73: (4) | AT73: (5)
D79: JUMLAH | O79: =SUM(O74:O78) -> 0 | Z79: =SUM(Z74:Z78) -> 0 | AH79: =SUM(AH74:AH78) -> 0 | AT79: =SUM(AT74:AT78) -> 0
D81: Apakah Anda mempunyai utang swasta luar negeri ? Jika "Ya", isilan Lampiran 11C
...
